Workbook
Name _GoBack: Ф5!#REF!
Name _GoBack: 'Ф-6 Заг'!$H$19
Name авто: [1]Ф3!$B$324:$B$332
Name авто: [2]Ф3!#REF!
Name авто: '[3]Форма 3,4'!$B$171:$B$180
Name авто: Ф2!#REF!
Name авто: Ф4!$B$128:$B$137
Name авто: Ф3!$B$324:$B$332
Name адм: [1]Ф3!$B$288:$B$306
Name адм: [2]Ф3!#REF!
Name адм: '[3]Форма 3,4'!$B$136:$B$154
Name адм: Ф2!#REF!
Name адм: Ф4!$B$93:$B$111
Name адм: Ф3!$B$288:$B$306
Name банно: [1]Ф3!$B$282:$B$285
Name банно: [2]Ф3!#REF!
Name банно: '[3]Форма 3,4'!$B$130:$B$133
Name банно: Ф2!#REF!
Name банно: Ф4!$B$87:$B$90
Name банно: Ф3!$B$282:$B$285
Name гибель: Ф1!$B$9:$B$10
Name да_нет: [1]пожар!$F$2:$F$3
Name да_нет: [4]пожар!$F$2:$F$3
Name да_нет: 'спасено людей'!$F$2:$F$3
Name да_нет: 'спасено мат.ценостей'!$F$2:$F$3
Name да_нет: ущерб!$F$2:$F$3
Name да_нет: пожар!$F$2:$F$3
Name детские: [1]Ф3!$B$254:$B$257
Name детские: [2]Ф3!#REF!
Name детские: '[3]Форма 3,4'!$B$102:$B$105
Name детские: Ф2!#REF!
Name детские: Ф4!$B$59:$B$62
Name детские: Ф3!$B$254:$B$257
Name жилой: [1]Ф3!$B$335:$B$341
Name жилой: [2]Ф3!#REF!
Name жилой: '[3]Форма 3,4'!$B$183:$B$189
Name жилой: Ф2!#REF!
Name жилой: Ф4!$B$140:$B$146
Name жилой: Ф3!$B$335:$B$341
Name жилые: Ф3!$B$335:$B$341
Name й: #REF!
Name й: #REF!
Name й: #REF!
Name й: #REF!
Name й: #REF!
Name й: #REF!
Name й: #REF!
Name й: #REF!
Name культурнозрелищные: [1]Ф3!$B$260:$B$265
Name культурнозрелищные: [2]Ф3!#REF!
Name культурнозрелищные: '[3]Форма 3,4'!$B$108:$B$113
Name культурнозрелищные: Ф2!#REF!
Name культурнозрелищные: Ф4!$B$65:$B$70
Name культурнозрелищные: Ф3!$B$260:$B$265
Name лес: [1]Ф3!$B$344:$B$345
Name лес: [2]Ф3!#REF!
Name лес: '[3]Форма 3,4'!$B$192:$B$193
Name лес: Ф2!#REF!
Name лес: Ф4!$B$149:$B$150
Name лес: Ф3!$B$344:$B$345

Sheet Данные
B1: с | C1: по
A2: ОТЧЕТ | B2: 42736 | C2: 43100
B4: да | C4: нет
A5: Аксуский
A6: Алакольский
A7: Балхашский
A8: Енбекшиказахский
A9: Ескельдинский
A10: Жамбылский
A11: Илийский
A12: Карасайский
A13: Каратальский
A14: Кербулакский
A15: Коксуский
A16: Панфиловский
... A24: ДЧС

Sheet Ф1
E1: (форма 1)
A2: Общие сведения о пожарах и гибели людей на территории Алматинской области
A4: Отчет за 2017 год | F4: январь | I4: % от общего числа | L4: Аксуский | O4: Алакольский | R4: Балхашский | U4: Енбекшиказахский | X4: Ескельдинский | AA4: Жамбылский | AD4: Илийский | AG4: Карасайский | AJ4: Каратальский | AM4: Кербулакский | AP4: Коксуский | AS4: Панфиловский | AV4: Райымбекский | AY4: Саркандский | BB4: Талгарский | BE4: Уйгурский | BH4: г.Талдыкорган | BK4: г.Капшагай | BN4: г.Текели
A5: № | B5: Наименование показателей | C5: всего | D5: в городах | E5: в сельской местности | F5: всего | G5: в городах | H5: в сельской местности | I5: всего | J5: в городах | K5: в сельской местности | L5: всего | M5: в городах | N5: в сельской местности | O5: всего | P5: в городах | Q5: в сельской местности | R5: всего | S5: в городах | T5: в сельской местности | U5: всего | V5: в городах | W5: в сельской местности | X5: всего | Y5: в городах | Z5: в сельской местности | AA5: всего | AB5: в городах | AC5: в сельской местности | AD5: всего | AE5: в городах | AF5: в сельской местности | AG5: всего | AH5: в городах | AI5: в сельской местности | AJ5: всего | AK5: в городах | AL5: в сельской местности | AM5: всего | AN5: в городах | AO5: в сельской местности | AP5: всего | AQ5: в городах | AR5: в сельской местности | AS5: всего | AT5: в городах | AU5: в сельской местности | AV5: всего | AW5: в городах | AX5: в сельской местности | AY5: всего | AZ5: в городах | BA5: в сельской местности | BB5: всего | BC5: в городах | BD5: в сельской местности | BE5: всего | BF5: в городах | BG5: в сельской местности | BH5: всего | BI5: в городах | BJ5: в сельской местности | BK5: всего | BL5: в городах | BM5: в сельской местности | BN5: всего | BO5: в городах | BP5: в сельской местности
